Traceback (most recent call last):
  File "/usr/local/lib/python3.10/dist-packages/jupyter_cache/executors/utils.py", line 58, in single_nb_execution
    executenb(
  File "/usr/local/lib/python3.10/dist-packages/nbclient/client.py", line 1305, in execute
    return NotebookClient(nb=nb, resources=resources, km=km, **kwargs).execute()
  File "/usr/local/lib/python3.10/dist-packages/jupyter_core/utils/__init__.py", line 166, in wrapped
    return loop.run_until_complete(inner)
  File "/usr/lib/python3.10/asyncio/base_events.py", line 649, in run_until_complete
    return future.result()
  File "/usr/local/lib/python3.10/dist-packages/nbclient/client.py", line 705, in async_execute
    await self.async_execute_cell(
  File "/usr/local/lib/python3.10/dist-packages/nbclient/client.py", line 1058, in async_execute_cell
    await self._check_raise_for_error(cell, cell_index, exec_reply)
  File "/usr/local/lib/python3.10/dist-packages/nbclient/client.py", line 914, in _check_raise_for_error
    raise CellExecutionError.from_cell_and_msg(cell, exec_reply_content)
nbclient.exceptions.CellExecutionError: An error occurred while executing the following cell:
------------------
dot_data = tree.export_graphviz(clf_gini, out_file=None, 
                              feature_names=X_train.columns,  
                              class_names=y_train.unique(),  
                              filled=True, rounded=True,  
                              special_characters=True)

graph = graphviz.Source(dot_data) 

graph 
------------------


[0;31m[0m
[0;31mNameError[0mTraceback (most recent call last)
[0;32m<ipython-input-12-34de2d8e9e5d>[0m in [0;36m<cell line: 1>[0;34m()[0m
[0;32m----> 1[0;31m dot_data = tree.export_graphviz(clf_gini, out_file=None, 
[0m[1;32m      2[0m                               [0mfeature_names[0m[0;34m=[0m[0mX_train[0m[0;34m.[0m[0mcolumns[0m[0;34m,[0m[0;34m[0m[0;34m[0m[0m
[1;32m      3[0m                               [0mclass_names[0m[0;34m=[0m[0my_train[0m[0;34m.[0m[0munique[0m[0;34m([0m[0;34m)[0m[0;34m,[0m[0;34m[0m[0;34m[0m[0m
[1;32m      4[0m                               [0mfilled[0m[0;34m=[0m[0;32mTrue[0m[0;34m,[0m [0mrounded[0m[0;34m=[0m[0;32mTrue[0m[0;34m,[0m[0;34m[0m[0;34m[0m[0m
[1;32m      5[0m                               special_characters=True)

[0;31mNameError[0m: name 'clf_gini' is not defined

